<?xml version="1.0" encoding="utf-8"?>
<!-- This URDF was automatically created by SolidWorks to URDF Exporter! Originally created by Stephen Brawner (brawner@gmail.com) 
     Commit Version: 1.6.0-4-g7f85cfe  Build Version: 1.6.7995.38578
     For more information, please see http://wiki.ros.org/sw_urdf_exporter -->
<robot
  name="RoboArmV2">
  <link
    name="base_link">
    <inertial>
      <origin
        xyz="0 -5.5511E-17 0.28321"
        rpy="0 0 0" />
      <mass
        value="72.196" />
      <inertia
        ixx="1.8115"
        ixy="2.4803E-33"
        ixz="1.9246E-33"
        iyy="1.8115"
        iyz="-4.2736E-18"
        izz="0.42299" />
    </inertial>
    <visual>
      <origin
        xyz="0 0 0"
        rpy="0 0 0" />
      <geometry>
        <mesh
          filename="package://RoboArmV2/meshes/base_link.STL" />
      </geometry>
      <material
        name="">
        <color
          rgba="1 0.72157 0.32941 1" />
      </material>
    </visual>
    <collision>
      <origin
        xyz="0 0 0"
        rpy="0 0 0" />
      <geometry>
        <mesh
          filename="package://RoboArmV2/meshes/base_link.STL" />
      </geometry>
    </collision>
  </link>
  <link
    name="Link_1">
    <inertial>
      <origin
        xyz="0.040291 -0.0046437 0.23736"
        rpy="0 0 0" />
      <mass
        value="82.991" />
      <inertia
        ixx="1.2041"
        ixy="0.082995"
        ixz="-0.04036"
        iyy="1.9146"
        iyz="0.0046514"
        izz="1.8233" />
    </inertial>
    <visual>
      <origin
        xyz="0 0 0"
        rpy="0 0 0" />
      <geometry>
        <mesh
          filename="package://RoboArmV2/meshes/Link_1.STL" />
      </geometry>
      <material
        name="">
        <color
          rgba="1 0.72157 0.32941 1" />
      </material>
    </visual>
    <collision>
      <origin
        xyz="0 0 0"
        rpy="0 0 0" />
      <geometry>
        <mesh
          filename="package://RoboArmV2/meshes/Link_1.STL" />
      </geometry>
    </collision>
  </link>
  <joint
    name="Joint_1"
    type="revolute">
    <origin
      xyz="0 0 0"
      rpy="0 0 0" />
    <parent
      link="base_link" />
    <child
      link="Link_1" />
    <axis
      xyz="0 0 1" />
    <limit
      lower="-4.15"
      upper="4.15"
      effort="20000"
      velocity="2" />
  </joint>
  <link
    name="Link_2">
    <inertial>
      <origin
        xyz="9.3913E-07 -0.006639 0.18023"
        rpy="0 0 0" />
      <mass
        value="41.932" />
      <inertia
        ixx="0.63144"
        ixy="-3.6307E-07"
        ixz="-5.8671E-08"
        iyy="0.64396"
        iyz="0.0055051"
        izz="0.21637" />
    </inertial>
    <visual>
      <origin
        xyz="0 0 0"
        rpy="0 0 0" />
      <geometry>
        <mesh
          filename="package://RoboArmV2/meshes/Link_2.STL" />
      </geometry>
      <material
        name="">
        <color
          rgba="1 0.72157 0.32941 1" />
      </material>
    </visual>
    <collision>
      <origin
        xyz="0 0 0"
        rpy="0 0 0" />
      <geometry>
        <mesh
          filename="package://RoboArmV2/meshes/Link_2.STL" />
      </geometry>
    </collision>
  </link>
  <joint
    name="Joint_2"
    type="revolute">
    <origin
      xyz="0.64572 -0.074426 0.24943"
      rpy="1.5708 0 -1.6855" />
    <parent
      link="Link_1" />
    <child
      link="Link_2" />
    <axis
      xyz="0 0 -1" />
    <limit
      lower="-4.15"
      upper="4.15"
      effort="20000"
      velocity="1" />
  </joint>
  <link
    name="Motor_1">
    <inertial>
      <origin
        xyz="-3.8858E-16 3.6082E-16 0.45"
        rpy="0 0 0" />
      <mass
        value="10.226" />
      <inertia
        ixx="0.049713"
        ixy="1.5769E-18"
        ixz="-2.1684E-17"
        iyy="0.049713"
        iyz="-1.3565E-17"
        izz="0.082382" />
    </inertial>
    <visual>
      <origin
        xyz="0 0 0"
        rpy="0 0 0" />
      <geometry>
        <mesh
          filename="package://RoboArmV2/meshes/Motor_1.STL" />
      </geometry>
      <material
        name="">
        <color
          rgba="0.54902 0.18039 0.18039 1" />
      </material>
    </visual>
    <collision>
      <origin
        xyz="0 0 0"
        rpy="0 0 0" />
      <geometry>
        <mesh
          filename="package://RoboArmV2/meshes/Motor_1.STL" />
      </geometry>
    </collision>
  </link>
  <joint
    name="Joint_2_Motor"
    type="fixed">
    <origin
      xyz="0 0 0"
      rpy="0 0 0" />
    <parent
      link="Link_2" />
    <child
      link="Motor_1" />
    <axis
      xyz="0 0 0" />
  </joint>
  <link
    name="Link_3">
    <inertial>
      <origin
        xyz="-2.2204E-16 -3.8858E-16 2.5975"
        rpy="0 0 0" />
      <mass
        value="292.92" />
      <inertia
        ixx="629.08"
        ixy="-2.5438E-18"
        ixz="2.8671E-15"
        iyy="629.08"
        iyz="1.0436E-14"
        izz="0.97965" />
    </inertial>
    <visual>
      <origin
        xyz="0 0 0"
        rpy="0 0 0" />
      <geometry>
        <mesh
          filename="package://RoboArmV2/meshes/Link_3.STL" />
      </geometry>
      <material
        name="">
        <color
          rgba="1 0.81176 0.50196 1" />
      </material>
    </visual>
    <collision>
      <origin
        xyz="0 0 0"
        rpy="0 0 0" />
      <geometry>
        <mesh
          filename="package://RoboArmV2/meshes/Link_3.STL" />
      </geometry>
    </collision>
  </link>
  <joint
    name="Joint_3"
    type="revolute">
    <origin
      xyz="0 0 0.2"
      rpy="1.5708 1.456 3.1416" />
    <parent
      link="Link_2" />
    <child
      link="Link_3" />
    <axis
      xyz="0 0 1" />
    <limit
      lower="-4.15"
      upper="4.15"
      effort="15000"
      velocity="2" />
  </joint>
  <link
    name="Motor_2">
    <inertial>
      <origin
        xyz="-1.1102E-16 3.3307E-16 0.1475"
        rpy="0 0 0" />
      <mass
        value="10.226" />
      <inertia
        ixx="0.049713"
        ixy="-5.5798E-20"
        ixz="-8.9354E-19"
        iyy="0.049713"
        iyz="9.7929E-18"
        izz="0.082382" />
    </inertial>
    <visual>
      <origin
        xyz="0 0 0"
        rpy="0 0 0" />
      <geometry>
        <mesh
          filename="package://RoboArmV2/meshes/Motor_2.STL" />
      </geometry>
      <material
        name="">
        <color
          rgba="0.54902 0.18039 0.18039 1" />
      </material>
    </visual>
    <collision>
      <origin
        xyz="0 0 0"
        rpy="0 0 0" />
      <geometry>
        <mesh
          filename="package://RoboArmV2/meshes/Motor_2.STL" />
      </geometry>
    </collision>
  </link>
  <joint
    name="Link_3_Motor_1"
    type="fixed">
    <origin
      xyz="0 0 0"
      rpy="0 0 0" />
    <parent
      link="Link_3" />
    <child
      link="Motor_2" />
    <axis
      xyz="0 0 0" />
  </joint>
  <link
    name="Motor_3">
    <inertial>
      <origin
        xyz="-2.2204E-16 1.4988E-15 5.0475"
        rpy="0 0 0" />
      <mass
        value="10.226" />
      <inertia
        ixx="0.049713"
        ixy="-3.4464E-20"
        ixz="9.318E-19"
        iyy="0.049713"
        iyz="8.7782E-18"
        izz="0.082382" />
    </inertial>
    <visual>
      <origin
        xyz="0 0 0"
        rpy="0 0 0" />
      <geometry>
        <mesh
          filename="package://RoboArmV2/meshes/Motor_3.STL" />
      </geometry>
      <material
        name="">
        <color
          rgba="0.54902 0.18039 0.18039 1" />
      </material>
    </visual>
    <collision>
      <origin
        xyz="0 0 0"
        rpy="0 0 0" />
      <geometry>
        <mesh
          filename="package://RoboArmV2/meshes/Motor_3.STL" />
      </geometry>
    </collision>
  </link>
  <joint
    name="Joint_3_Motor_2"
    type="fixed">
    <origin
      xyz="0 0 0"
      rpy="0 0 0" />
    <parent
      link="Link_3" />
    <child
      link="Motor_3" />
    <axis
      xyz="0 0 0" />
  </joint>
  <link
    name="Link_4">
    <inertial>
      <origin
        xyz="0.084944 -0.0097912 5.1993"
        rpy="0 0 0" />
      <mass
        value="65.228" />
      <inertia
        ixx="0.29538"
        ixy="0.21926"
        ixz="0.023646"
        iyy="2.1724"
        iyz="-0.0027302"
        izz="2.2095" />
    </inertial>
    <visual>
      <origin
        xyz="0 0 0"
        rpy="0 0 0" />
      <geometry>
        <mesh
          filename="package://RoboArmV2/meshes/Link_4.STL" />
      </geometry>
      <material
        name="">
        <color
          rgba="1 0.72157 0.32941 1" />
      </material>
    </visual>
    <collision>
      <origin
        xyz="0 0 0"
        rpy="0 0 0" />
      <geometry>
        <mesh
          filename="package://RoboArmV2/meshes/Link_4.STL" />
      </geometry>
    </collision>
  </link>
  <joint
    name="Joint_4"
    type="fixed">
    <origin
      xyz="0 0 0"
      rpy="0 0 0" />
    <parent
      link="Link_3" />
    <child
      link="Link_4" />
    <axis
      xyz="0 0 0" />
  </joint>
  <link
    name="Link_5">
    <inertial>
      <origin
        xyz="9.3913E-07 -0.006639 0.18023"
        rpy="0 0 0" />
      <mass
        value="41.932" />
      <inertia
        ixx="0.63144"
        ixy="-3.6307E-07"
        ixz="-5.8671E-08"
        iyy="0.64396"
        iyz="0.0055051"
        izz="0.21637" />
    </inertial>
    <visual>
      <origin
        xyz="0 0 0"
        rpy="0 0 0" />
      <geometry>
        <mesh
          filename="package://RoboArmV2/meshes/Link_5.STL" />
      </geometry>
      <material
        name="">
        <color
          rgba="1 0.72157 0.32941 1" />
      </material>
    </visual>
    <collision>
      <origin
        xyz="0 0 0"
        rpy="0 0 0" />
      <geometry>
        <mesh
          filename="package://RoboArmV2/meshes/Link_5.STL" />
      </geometry>
    </collision>
  </link>
  <joint
    name="Joint_5"
    type="revolute">
    <origin
      xyz="0.74507 -0.085876 5.195"
      rpy="1.5708 0 -1.6855" />
    <parent
      link="Link_4" />
    <child
      link="Link_5" />
    <axis
      xyz="0 0 -1" />
    <limit
      lower="-4.15"
      upper="4.15"
      effort="10000"
      velocity="2" />
  </joint>
  <link
    name="Motor_4">
    <inertial>
      <origin
        xyz="1.1102E-16 0 0.475"
        rpy="0 0 0" />
      <mass
        value="15.339" />
      <inertia
        ixx="0.090547"
        ixy="5.0283E-18"
        ixz="1.2143E-17"
        iyy="0.090547"
        iyz="1.2028E-18"
        izz="0.12357" />
    </inertial>
    <visual>
      <origin
        xyz="0 0 0"
        rpy="0 0 0" />
      <geometry>
        <mesh
          filename="package://RoboArmV2/meshes/Motor_4.STL" />
      </geometry>
      <material
        name="">
        <color
          rgba="0.54902 0.18039 0.18039 1" />
      </material>
    </visual>
    <collision>
      <origin
        xyz="0 0 0"
        rpy="0 0 0" />
      <geometry>
        <mesh
          filename="package://RoboArmV2/meshes/Motor_4.STL" />
      </geometry>
    </collision>
  </link>
  <joint
    name="Joint_5_Motor"
    type="fixed">
    <origin
      xyz="0 0 0"
      rpy="0 0 0" />
    <parent
      link="Link_5" />
    <child
      link="Motor_4" />
    <axis
      xyz="0 0 0" />
  </joint>
  <link
    name="Link_6">
    <inertial>
      <origin
        xyz="0 0 2.5975"
        rpy="0 0 0" />
      <mass
        value="292.92" />
      <inertia
        ixx="629.08"
        ixy="-3.2859E-17"
        ixz="-4.9206E-15"
        iyy="629.08"
        iyz="1.0014E-15"
        izz="0.97965" />
    </inertial>
    <visual>
      <origin
        xyz="0 0 0"
        rpy="0 0 0" />
      <geometry>
        <mesh
          filename="package://RoboArmV2/meshes/Link_6.STL" />
      </geometry>
      <material
        name="">
        <color
          rgba="1 0.81176 0.50196 1" />
      </material>
    </visual>
    <collision>
      <origin
        xyz="0 0 0"
        rpy="0 0 0" />
      <geometry>
        <mesh
          filename="package://RoboArmV2/meshes/Link_6.STL" />
      </geometry>
    </collision>
  </link>
  <joint
    name="Joint_6"
    type="fixed">
    <origin
      xyz="0 5.195 0.2"
      rpy="1.5708 -1.456 0" />
    <parent
      link="Link_5" />
    <child
      link="Link_6" />
    <axis
      xyz="0 0 0" />
  </joint>
  <link
    name="Motor_5">
    <inertial>
      <origin
        xyz="1.9984E-15 -2.2204E-16 5.0475"
        rpy="0 0 0" />
      <mass
        value="10.226" />
      <inertia
        ixx="0.049713"
        ixy="-7.2472E-18"
        ixz="2.714E-18"
        iyy="0.049713"
        iyz="-9.2574E-19"
        izz="0.082382" />
    </inertial>
    <visual>
      <origin
        xyz="0 0 0"
        rpy="0 0 0" />
      <geometry>
        <mesh
          filename="package://RoboArmV2/meshes/Motor_5.STL" />
      </geometry>
      <material
        name="">
        <color
          rgba="0.54902 0.18039 0.18039 1" />
      </material>
    </visual>
    <collision>
      <origin
        xyz="0 0 0"
        rpy="0 0 0" />
      <geometry>
        <mesh
          filename="package://RoboArmV2/meshes/Motor_5.STL" />
      </geometry>
    </collision>
  </link>
  <joint
    name="Joint_6_Motor1"
    type="fixed">
    <origin
      xyz="0 0 0"
      rpy="0 0 0" />
    <parent
      link="Link_6" />
    <child
      link="Motor_5" />
    <axis
      xyz="0 0 0" />
  </joint>
  <link
    name="Motor_6">
    <inertial>
      <origin
        xyz="0 1.33226762955019E-15 0.147500000000001"
        rpy="0 0 0" />
      <mass
        value="10.2258843073462" />
      <inertia
        ixx="0.0497127104816508"
        ixy="-3.15096263154878E-19"
        ixz="1.81287701888851E-18"
        iyy="0.0497127104816508"
        iyz="-8.75216182068354E-18"
        izz="0.082382280451058" />
    </inertial>
    <visual>
      <origin
        xyz="0 0 0"
        rpy="0 0 0" />
      <geometry>
        <mesh
          filename="package://RoboArmV2/meshes/Motor_6.STL" />
      </geometry>
      <material
        name="">
        <color
          rgba="0.549019607843137 0.180392156862745 0.180392156862745 1" />
      </material>
    </visual>
    <collision>
      <origin
        xyz="0 0 0"
        rpy="0 0 0" />
      <geometry>
        <mesh
          filename="package://RoboArmV2/meshes/Motor_6.STL" />
      </geometry>
    </collision>
  </link>
  <joint
    name="Joint_6_Motor2"
    type="fixed">
    <origin
      xyz="0 0 0"
      rpy="0 0 0" />
    <parent
      link="Link_6" />
    <child
      link="Motor_6" />
    <axis
      xyz="0 0 0" />
  </joint>
  <link
    name="Link_7">
    <inertial>
      <origin
        xyz="0.01964 0.0022627 -0.0066391"
        rpy="0 0 0" />
      <mass
        value="41.932" />
      <inertia
        ixx="0.22182"
        ixy="-0.047213"
        ixz="-0.0054689"
        iyy="0.62599"
        iyz="-0.00062999"
        izz="0.64396" />
    </inertial>
    <visual>
      <origin
        xyz="0 0 0"
        rpy="0 0 0" />
      <geometry>
        <mesh
          filename="package://RoboArmV2/meshes/Link_7.STL" />
      </geometry>
      <material
        name="">
        <color
          rgba="1 0.72157 0.32941 1" />
      </material>
    </visual>
    <collision>
      <origin
        xyz="0 0 0"
        rpy="0 0 0" />
      <geometry>
        <mesh
          filename="package://RoboArmV2/meshes/Link_7.STL" />
      </geometry>
    </collision>
  </link>
  <joint
    name="Joint_7"
    type="revolute">
    <origin
      xyz="0 0 0"
      rpy="0 0 0" />
    <parent
      link="Link_6" />
    <child
      link="Link_7" />
    <axis
      xyz="0 0 1" />
    <limit
      lower="-4.15"
      upper="4.15"
      effort="20000"
      velocity="1" />
  </joint>
  <link
    name="Motor_7">
    <inertial>
      <origin
        xyz="-3.3307E-16 -3.5527E-15 0.45"
        rpy="0 0 0" />
      <mass
        value="10.226" />
      <inertia
        ixx="0.049713"
        ixy="2.325E-18"
        ixz="-1.0842E-17"
        iyy="0.049713"
        iyz="5.6333E-18"
        izz="0.082382" />
    </inertial>
    <visual>
      <origin
        xyz="0 0 0"
        rpy="0 0 0" />
      <geometry>
        <mesh
          filename="package://RoboArmV2/meshes/Motor_7.STL" />
      </geometry>
      <material
        name="">
        <color
          rgba="0.54902 0.18039 0.18039 1" />
      </material>
    </visual>
    <collision>
      <origin
        xyz="0 0 0"
        rpy="0 0 0" />
      <geometry>
        <mesh
          filename="package://RoboArmV2/meshes/Motor_7.STL" />
      </geometry>
    </collision>
  </link>
  <joint
    name="Joint_7_Motor"
    type="fixed">
    <origin
      xyz="0.198684611746515 0.02290032871242 0"
      rpy="-1.5707963267949 0 1.68554965613893" />
    <parent
      link="Link_7" />
    <child
      link="Motor_7" />
    <axis
      xyz="0 0 0" />
  </joint>
  <link
    name="Link_8">
    <inertial>
      <origin
        xyz="2.0431E-07 0.01207 0.60944"
        rpy="0 0 0" />
      <mass
        value="82.991" />
      <inertia
        ixx="1.9241"
        ixy="3.8424E-07"
        ixz="-4.6678E-07"
        iyy="1.8233"
        iyz="-0.040627"
        izz="1.1945" />
    </inertial>
    <visual>
      <origin
        xyz="0 0 0"
        rpy="0 0 0" />
      <geometry>
        <mesh
          filename="package://RoboArmV2/meshes/Link_8.STL" />
      </geometry>
      <material
        name="">
        <color
          rgba="1 0.72157 0.32941 1" />
      </material>
    </visual>
    <collision>
      <origin
        xyz="0 0 0"
        rpy="0 0 0" />
      <geometry>
        <mesh
          filename="package://RoboArmV2/meshes/Link_8.STL" />
      </geometry>
    </collision>
  </link>
  <joint
    name="Joint_8"
    type="revolute">
    <origin
      xyz="0.19868 0.0229 0"
      rpy="-1.5708 0 1.6855" />
    <parent
      link="Link_7" />
    <child
      link="Link_8" />
    <axis
      xyz="0 0 -1" />
    <limit
      lower="-4.15"
      upper="4.15"
      effort="20000"
      velocity="1" />
  </joint>
  <link
    name="Link_9">
    <inertial>
      <origin
        xyz="0 0 0.21679"
        rpy="0 0 0" />
      <mass
        value="72.196" />
      <inertia
        ixx="1.8115"
        ixy="-5.9291E-17"
        ixz="-1.6335E-16"
        iyy="1.8115"
        iyz="-6.4559E-17"
        izz="0.42299" />
    </inertial>
    <visual>
      <origin
        xyz="0 0 0"
        rpy="0 0 0" />
      <geometry>
        <mesh
          filename="package://RoboArmV2/meshes/Link_9.STL" />
      </geometry>
      <material
        name="">
        <color
          rgba="1 0.72157 0.32941 1" />
      </material>
    </visual>
    <collision>
      <origin
        xyz="0 0 0"
        rpy="0 0 0" />
      <geometry>
        <mesh
          filename="package://RoboArmV2/meshes/Link_9.STL" />
      </geometry>
    </collision>
  </link>
  <joint
    name="Joint_9"
    type="revolute">
    <origin
      xyz="0 -0.25057 0.65"
      rpy="-1.5708 -1.456 0" />
    <parent
      link="Link_8" />
    <child
      link="Link_9" />
    <axis
      xyz="0 0 -1" />
    <limit
      lower="-4.15"
      upper="4.15"
      effort="20000"
      velocity="2" />
  </joint>
</robot>